promise.then(f1).catch(f2);
//Против:

promise.then(f1, f2);

//ОТВЕТ: Нет, они ведут себя не одинакого.
//Первый вариант выполняет f1 в случае успеха и f2 в случае ошибки.
//Второй вариант выполнит f1  в случе успеха, но f2 будет выполнена, только если и дальше ошибок не будеь.
//Если f1выдат ошибку, то до f2 выполнение не дойдет